<?xml version="1.0" ?>
<robot name="Robot" xmlns:xacro="http://www.ros.org/wiki/xacro">

<xacro:include filename="materials.xacro" />
<xacro:include filename="Robot.trans" />
<xacro:include filename="Robot.gazebo" />

<link name="base_link">
  <visual>
    <origin xyz="0 0 0" rpy="0 0 0"/>
    <geometry>
      <mesh filename="package://robot_description/meshes/base_link.stl" scale="0.001 0.001 0.001"/>
    </geometry>
    <material name="silver"/>
  </visual>
  <collision>
    <origin xyz="0 0 0" rpy="0 0 0"/>
    <geometry>
      <mesh filename="package://robot_description/meshes/base_link.stl" scale="0.001 0.001 0.001"/>
    </geometry>
  </collision>
</link>

<link name="link1_1">
  <visual>
    <origin xyz="0 0 0" rpy="0 0 0"/>
    <geometry>
      <mesh filename="package://robot_description/meshes/link1_1.stl" scale="0.001 0.001 0.001"/>
    </geometry>
    <material name="silver"/>
  </visual>
  <collision>
    <origin xyz="0 0 0" rpy="0 0 0"/>
    <geometry>
      <mesh filename="package://robot_description/meshes/link1_1.stl" scale="0.001 0.001 0.001"/>
    </geometry>
  </collision>
</link>

<link name="link2_1">
  <visual>
    <origin xyz="0 0 0" rpy="0 0 0"/>
    <geometry>
      <mesh filename="package://robot_description/meshes/link2_1.stl" scale="0.001 0.001 0.001"/>
    </geometry>
    <material name="silver"/>
  </visual>
  <collision>
    <origin xyz="0 0 0" rpy="0 0 0"/>
    <geometry>
      <mesh filename="package://robot_description/meshes/link2_1.stl" scale="0.001 0.001 0.001"/>
    </geometry>
  </collision>
</link>

<link name="link3_1">
  <visual>
    <origin xyz="0 0 0" rpy="0 0 0"/>
    <geometry>
      <mesh filename="package://robot_description/meshes/link3_1.stl" scale="0.001 0.001 0.001"/>
    </geometry>
    <material name="silver"/>
  </visual>
  <collision>
    <origin xyz="0 0 0" rpy="0 0 0"/>
    <geometry>
      <mesh filename="package://robot_description/meshes/link3_1.stl" scale="0.001 0.001 0.001"/>
    </geometry>
  </collision>
</link>

<link name="link4_1">
  <visual>
    <origin xyz="0 0 0" rpy="0 0 0"/>
    <geometry>
      <mesh filename="package://robot_description/meshes/link4_1.stl" scale="0.001 0.001 0.001"/>
    </geometry>
    <material name="silver"/>
  </visual>
  <collision>
    <origin xyz="0 0 0" rpy="0 0 0"/>
    <geometry>
      <mesh filename="package://robot_description/meshes/link4_1.stl" scale="0.001 0.001 0.001"/>
    </geometry>
  </collision>
</link>

<link name="link5_1">
  <visual>
    <origin xyz="0 0 0" rpy="0 0 0"/>
    <geometry>
      <mesh filename="package://robot_description/meshes/link5_1.stl" scale="0.001 0.001 0.001"/>
    </geometry>
    <material name="silver"/>
  </visual>
  <collision>
    <origin xyz="0 0 0" rpy="0 0 0"/>
    <geometry>
      <mesh filename="package://robot_description/meshes/link5_1.stl" scale="0.001 0.001 0.001"/>
    </geometry>
  </collision>
</link>

<link name="link6_1">
  <visual>
    <origin xyz="0 0 0" rpy="0 0 0"/>
    <geometry>
      <mesh filename="package://robot_description/meshes/link6_1.stl" scale="0.001 0.001 0.001"/>
    </geometry>
    <material name="silver"/>
  </visual>
  <collision>
    <origin xyz="0 0 0" rpy="0 0 0"/>
    <geometry>
      <mesh filename="package://robot_description/meshes/link6_1.stl" scale="0.001 0.001 0.001"/>
    </geometry>
  </collision>
</link>

<link name="Servo_Gear_1">
  <visual>
    <origin xyz="0 0 0" rpy="0 0 0"/>
    <geometry>
      <mesh filename="package://robot_description/meshes/Servo_Gear.stl" scale="0.001 0.001 0.001"/>
    </geometry>
    <material name="silver"/>
  </visual>
  <collision>
    <origin xyz="0 0 0" rpy="0 0 0"/>
    <geometry>
      <mesh filename="package://robot_description/meshes/Servo_Gear.stl" scale="0.001 0.001 0.001"/>
    </geometry>
  </collision>
</link>

<link name="Pivot_Servo">
  <visual>
    <origin xyz="0 0 0" rpy="0 0 0"/>
    <geometry>
      <mesh filename="package://robot_description/meshes/Pivot_Arm.stl" scale="0.001 0.001 0.001"/>
    </geometry>
    <material name="silver"/>
  </visual>
  <collision>
    <origin xyz="0 0 0" rpy="0 0 0"/>
    <geometry>
      <mesh filename="package://robot_description/meshes/Pivot_Arm.stl" scale="0.001 0.001 0.001"/>
    </geometry>
  </collision>
</link>

<link name="Gripper_Servo">
  <visual>
    <origin xyz="0 0 0" rpy="0 0 0"/>
    <geometry>
      <mesh filename="package://robot_description/meshes/Gripper_Servo.stl" scale="0.001 0.001 0.001"/>
    </geometry>
    <material name="silver"/>
  </visual>
  <collision>
    <origin xyz="0 0 0" rpy="0 0 0"/>
    <geometry>
      <mesh filename="package://robot_description/meshes/Gripper_Servo.stl" scale="0.001 0.001 0.001"/>
    </geometry>
  </collision>
</link>

<link name="Idol_Gear_1">
  <visual>
    <origin xyz="0 0 0" rpy="0 0 0"/>
    <geometry>
      <mesh filename="package://robot_description/meshes/Idol_Gear.stl" scale="0.001 0.001 0.001"/>
    </geometry>
    <material name="silver"/>
  </visual>
  <collision>
    <origin xyz="0 0 0" rpy="0 0 0"/>
    <geometry>
      <mesh filename="package://robot_description/meshes/Idol_Gear.stl" scale="0.001 0.001 0.001"/>
    </geometry>
  </collision>
</link>

<link name="Pivot_Idol">
  <visual>
    <origin xyz="0 0 0" rpy="0 0 0"/>
    <geometry>
      <mesh filename="package://robot_description/meshes/Pivot_Arm.stl" scale="0.001 0.001 0.001"/>
    </geometry>
    <material name="silver"/>
  </visual>
  <collision>
    <origin xyz="0 0 0" rpy="0 0 0"/>
    <geometry>
      <mesh filename="package://robot_description/meshes/Pivot_Arm.stl" scale="0.001 0.001 0.001"/>
    </geometry>
  </collision>
</link>

<link name="Gripper_Idol">
  <visual>
    <origin xyz="0 0 0" rpy="0 0 0"/>
    <geometry>
      <mesh filename="package://robot_description/meshes/Gripper_Idol.stl" scale="0.001 0.001 0.001"/>
    </geometry>
    <material name="silver"/>
  </visual>
  <collision>
    <origin xyz="0 0 0" rpy="0 0 0"/>
    <geometry>
      <mesh filename="package://robot_description/meshes/Gripper_Idol.stl" scale="0.001 0.001 0.001"/>
    </geometry>
  </collision>
</link>

<joint name="Joint1" type="revolute">
  <origin xyz="-7e-06 4e-06 0.065" rpy="0 0 0"/>
  <parent link="base_link"/>
  <child link="link1_1"/>
  <axis xyz="-0.000105 6.8e-05 1.0"/>
  <limit upper="1.658" lower="-1.658" effort="100" velocity="100.0"/>
</joint>

<joint name="Joint2" type="revolute">
  <origin xyz="0 0 0.1655" rpy="0 0 0"/>
  <parent link="link1_1"/>
  <child link="link2_1"/>
  <axis xyz="0 1 0"/>
  <limit upper="1.92" lower="-0.873" effort="100" velocity="100.0"/>
</joint>

<joint name="Joint3" type="revolute">
  <origin xyz="0.0025 0 0.222" rpy="0 0 0"/>
  <parent link="link2_1"/>
  <child link="link3_1"/>
  <axis xyz="0 1 0"/>
  <limit upper="2.10" lower="-2.10" effort="100" velocity="100.0"/>
</joint>

<joint name="Joint4" type="revolute">
  <origin xyz="0 0 0.1291" rpy="0 0 3.14159"/>
  <parent link="link3_1"/>
  <child link="link4_1"/>
  <axis xyz="0 0 1"/>
  <limit upper="2.36" lower="-2.36" effort="100" velocity="100.0"/>
</joint>

<joint name="Joint5" type="revolute">
  <origin xyz="0 0 0.095" rpy="0 0 0"/>
  <parent link="link4_1"/>
  <child link="link5_1"/>
  <axis xyz="0 -1 0"/>
  <limit upper="1.7" lower="-1.7" effort="100" velocity="100.0"/>
</joint>

<joint name="Joint6" type="revolute">
  <origin xyz="0 0 0.0469" rpy="0 0 0"/>
  <parent link="link5_1"/>
  <child link="link6_1"/>
  <axis xyz="0 0 1"/>
  <limit upper="2.36" lower="-2.36" effort="100" velocity="100.0"/>
</joint>

<joint name="Servo Joint" type="revolute">
  <origin xyz="0 -0.014 0.024" rpy="0 -1.5708 0"/>
  <parent link="link6_1"/>
  <child link="Servo_Gear_1"/>
  <axis xyz="0 0 1"/>
  <limit upper="0" lower="-1.5708" effort="100" velocity="100.0"/>
</joint>

<joint name="Pivot Servo Joint" type="revolute">
  <origin xyz="0 -0.007 0.044" rpy="0 -1.5708 0"/>
  <parent link="link6_1"/>
  <child link="Pivot_Servo"/>
  <mimic joint="Servo Joint"/>
  <axis xyz="0 0 1"/>
  <limit upper="3.14" lower="-3.14" effort="100" velocity="100.0"/>
</joint>

<joint name="Gripper Servo Joint" type="revolute">
  <origin xyz="0.04 0 0" rpy="0 0 0"/>
  <parent link="Servo_Gear_1"/>
  <child link="Gripper_Servo"/>
  <mimic joint="Servo Joint" multiplier="-1.0"/>
  <axis xyz="0 0 1"/>
  <limit upper="3.14" lower="-3.14" effort="100" velocity="100.0"/>
</joint>

<joint name="Idol Joint" type="revolute">
  <origin xyz="0 0.014 0.024" rpy="0 -1.5708 0"/>
  <parent link="link6_1"/>
  <child link="Idol_Gear_1"/>
  <mimic joint="Servo Joint"/>
  <axis xyz="0 0 -1"/>
  <limit upper="0" lower="-1.5708" effort="100" velocity="100.0"/>
</joint>

<joint name="Pivot Idol Joint" type="revolute">
  <origin xyz="0 0.007 0.044" rpy="0 -1.5708 0"/>
  <parent link="link6_1"/>
  <child link="Pivot_Idol"/>
  <mimic joint="Pivot Servo Joint"/>
  <axis xyz="0 0 -1"/>
  <limit upper="3.14" lower="-3.14" effort="100" velocity="100.0"/>
</joint>

<joint name="Gripper Idol Joint" type="revolute">
  <origin xyz="0.04 0 0" rpy="0 0 0"/>
  <parent link="Idol_Gear_1"/>
  <child link="Gripper_Idol"/>
  <mimic joint="Idol Joint" multiplier="1.0"/>
  <axis xyz="0 0 1"/>
  <limit upper="3.14" lower="-3.14" effort="100" velocity="100.0"/>
</joint>

</robot>
