<?xml version="1.0" ?>
<robot name="Robot" xmlns:xacro="http://www.ros.org/wiki/xacro">

<xacro:include filename="$(find Robot_description)/urdf/materials.xacro" />
<xacro:include filename="$(find Robot_description)/urdf/Robot.trans" />
<xacro:include filename="$(find Robot_description)/urdf/Robot.gazebo" />
<link name="base_link">
  <inertial>
    <origin xyz="-0.014292847308119921 0.029643182358033662 0.2156805462258431" rpy="0 0 0"/>
    <mass value="0.6555115079798821"/>
    <inertia ixx="0.00156" iyy="0.00156" izz="0.002692" ixy="1e-06" iyz="4.7e-05" ixz="3.6e-05"/>
  </inertial>
  <visual>
    <origin xyz="0 0 0" rpy="0 0 0"/>
    <geometry>
      <mesh filename="package://Robot_description/meshes/base_link.stl" scale="0.001 0.001 0.001"/>
    </geometry>
    <material name="silver"/>
  </visual>
  <collision>
    <origin xyz="0 0 0" rpy="0 0 0"/>
    <geometry>
      <mesh filename="package://Robot_description/meshes/base_link.stl" scale="0.001 0.001 0.001"/>
    </geometry>
  </collision>
</link>

<link name="link5_1">
  <inertial>
    <origin xyz="-0.5787989415015174 0.12275388985793549 0.31169295695122023" rpy="0 0 0"/>
    <mass value="0.1607410659493192"/>
    <inertia ixx="9.8e-05" iyy="9.1e-05" izz="8.5e-05" ixy="-7e-06" iyz="-2e-06" ixz="-1.3e-05"/>
  </inertial>
  <visual>
    <origin xyz="-0.682077 0.098996 -0.519354" rpy="0 0 0"/>
    <geometry>
      <mesh filename="package://Robot_description/meshes/link5_1.stl" scale="0.001 0.001 0.001"/>
    </geometry>
    <material name="silver"/>
  </visual>
  <collision>
    <origin xyz="-0.682077 0.098996 -0.519354" rpy="0 0 0"/>
    <geometry>
      <mesh filename="package://Robot_description/meshes/link5_1.stl" scale="0.001 0.001 0.001"/>
    </geometry>
  </collision>
</link>

<link name="Servo_Gear_1">
  <inertial>
    <origin xyz="0.042213503915512485 0.0051962019055995234 0.014177807555517785" rpy="0 0 0"/>
    <mass value="0.015458635829547249"/>
    <inertia ixx="4e-06" iyy="1.5e-05" izz="1.2e-05" ixy="-1e-06" iyz="-1e-06" ixz="-6e-06"/>
  </inertial>
  <visual>
    <origin xyz="-0.15265 -0.037988 -0.883301" rpy="0 0 0"/>
    <geometry>
      <mesh filename="package://Robot_description/meshes/Servo_Gear_1.stl" scale="0.001 0.001 0.001"/>
    </geometry>
    <material name="silver"/>
  </visual>
  <collision>
    <origin xyz="-0.15265 -0.037988 -0.883301" rpy="0 0 0"/>
    <geometry>
      <mesh filename="package://Robot_description/meshes/Servo_Gear_1.stl" scale="0.001 0.001 0.001"/>
    </geometry>
  </collision>
</link>

<link name="Idol_Gear_1">
  <inertial>
    <origin xyz="0.013036481081125345 0.01802179741945479 0.0390997266023575" rpy="0 0 0"/>
    <mass value="0.01558102330322005"/>
    <inertia ixx="1.3e-05" iyy="1.5e-05" izz="5e-06" ixy="-2e-06" iyz="-4e-06" ixz="-5e-06"/>
  </inertial>
  <visual>
    <origin xyz="-0.129063 -0.045204 -0.896558" rpy="0 0 0"/>
    <geometry>
      <mesh filename="package://Robot_description/meshes/Idol_Gear_1.stl" scale="0.001 0.001 0.001"/>
    </geometry>
    <material name="silver"/>
  </visual>
  <collision>
    <origin xyz="-0.129063 -0.045204 -0.896558" rpy="0 0 0"/>
    <geometry>
      <mesh filename="package://Robot_description/meshes/Idol_Gear_1.stl" scale="0.001 0.001 0.001"/>
    </geometry>
  </collision>
</link>

<link name="link6_1">
  <inertial>
    <origin xyz="-0.5075102476235241 0.14054545458469847 0.47602765621186643" rpy="0 0 0"/>
    <mass value="0.01865052429923146"/>
    <inertia ixx="7e-06" iyy="1.2e-05" izz="9e-06" ixy="-1e-06" iyz="-1e-06" ixz="2e-06"/>
  </inertial>
  <visual>
    <origin xyz="-0.646863 0.103905 -0.410506" rpy="0 0 0"/>
    <geometry>
      <mesh filename="package://Robot_description/meshes/link6_1.stl" scale="0.001 0.001 0.001"/>
    </geometry>
    <material name="silver"/>
  </visual>
  <collision>
    <origin xyz="-0.646863 0.103905 -0.410506" rpy="0 0 0"/>
    <geometry>
      <mesh filename="package://Robot_description/meshes/link6_1.stl" scale="0.001 0.001 0.001"/>
    </geometry>
  </collision>
</link>

<link name="link1_1">
  <inertial>
    <origin xyz="0.0023156662716766075 0.0033004673099537654 0.08017793458058617" rpy="0 0 0"/>
    <mass value="1.9598700732514862"/>
    <inertia ixx="0.012654" iyy="0.009611" izz="0.008747" ixy="-0.001148" iyz="-9e-06" ixz="-7.9e-05"/>
  </inertial>
  <visual>
    <origin xyz="0.013437 -0.030771 -0.24298" rpy="0 0 0"/>
    <geometry>
      <mesh filename="package://Robot_description/meshes/link1_1.stl" scale="0.001 0.001 0.001"/>
    </geometry>
    <material name="silver"/>
  </visual>
  <collision>
    <origin xyz="0.013437 -0.030771 -0.24298" rpy="0 0 0"/>
    <geometry>
      <mesh filename="package://Robot_description/meshes/link1_1.stl" scale="0.001 0.001 0.001"/>
    </geometry>
  </collision>
</link>

<link name="link2_1">
  <inertial>
    <origin xyz="0.3566543899352841 -0.13176479567010627 0.10158651938434693" rpy="0 0 0"/>
    <mass value="1.9144645074140343"/>
    <inertia ixx="0.016598" iyy="0.015993" izz="0.003586" ixy="-0.00025" iyz="-0.000575" ixz="-0.000586"/>
  </inertial>
  <visual>
    <origin xyz="0.360772 -0.174058 -0.385169" rpy="0 0 0"/>
    <geometry>
      <mesh filename="package://Robot_description/meshes/link2_1.stl" scale="0.001 0.001 0.001"/>
    </geometry>
    <material name="silver"/>
  </visual>
  <collision>
    <origin xyz="0.360772 -0.174058 -0.385169" rpy="0 0 0"/>
    <geometry>
      <mesh filename="package://Robot_description/meshes/link2_1.stl" scale="0.001 0.001 0.001"/>
    </geometry>
  </collision>
</link>

<link name="link3_1">
  <inertial>
    <origin xyz="0.0625690601145066 0.028676445255615537 0.7485166997896099" rpy="0 0 0"/>
    <mass value="0.7274515218419347"/>
    <inertia ixx="0.001771" iyy="0.002065" izz="0.000964" ixy="7.2e-05" iyz="0.000116" ixz="-0.000543"/>
  </inertial>
  <visual>
    <origin xyz="0.042994 -0.012782 0.08255" rpy="0 0 0"/>
    <geometry>
      <mesh filename="package://Robot_description/meshes/link3_1.stl" scale="0.001 0.001 0.001"/>
    </geometry>
    <material name="silver"/>
  </visual>
  <collision>
    <origin xyz="0.042994 -0.012782 0.08255" rpy="0 0 0"/>
    <geometry>
      <mesh filename="package://Robot_description/meshes/link3_1.stl" scale="0.001 0.001 0.001"/>
    </geometry>
  </collision>
</link>

<link name="link4_1">
  <inertial>
    <origin xyz="0.5607858303557733 -0.20177401958703842 -0.11984578157368675" rpy="0 0 0"/>
    <mass value="0.32455418653717066"/>
    <inertia ixx="0.000539" iyy="0.000673" izz="0.00038" ixy="4.2e-05" iyz="1e-05" ixz="-9.2e-05"/>
  </inertial>
  <visual>
    <origin xyz="0.478036 -0.227798 -0.908418" rpy="0 0 0"/>
    <geometry>
      <mesh filename="package://Robot_description/meshes/link4_1.stl" scale="0.001 0.001 0.001"/>
    </geometry>
    <material name="silver"/>
  </visual>
  <collision>
    <origin xyz="0.478036 -0.227798 -0.908418" rpy="0 0 0"/>
    <geometry>
      <mesh filename="package://Robot_description/meshes/link4_1.stl" scale="0.001 0.001 0.001"/>
    </geometry>
  </collision>
</link>

<joint name="Joint5" type="revolute">
  <origin xyz="1.160113 -0.326794 -0.389064" rpy="0 0 0"/>
  <parent link="link4_1"/>
  <child link="link5_1"/>
  <axis xyz="0.83757 -0.303178 -0.454488"/>
  <limit upper="1.832596" lower="-1.832596" effort="100" velocity="100"/>
</joint>

<joint name="Servo Joint" type="revolute">
  <origin xyz="-0.494213 0.141893 0.472795" rpy="0 0 0"/>
  <parent link="link6_1"/>
  <child link="Servo_Gear_1"/>
  <axis xyz="-0.08842 -0.921499 0.378182"/>
  <limit upper="0.523599" lower="-0.610865" effort="100" velocity="100"/>
</joint>

<joint name="Idol Joint" type="revolute">
  <origin xyz="-0.5178 0.149109 0.486052" rpy="0 0 0"/>
  <parent link="link6_1"/>
  <child link="Idol_Gear_1"/>
  <axis xyz="-0.08842 -0.921499 0.378182"/>
  <limit upper="0.959931" lower="-0.174533" effort="100" velocity="100"/>
</joint>

<joint name="Joint6" type="revolute">
  <origin xyz="-0.035214 -0.004909 -0.108848" rpy="0 0 0"/>
  <parent link="link5_1"/>
  <child link="link6_1"/>
  <axis xyz="0.533765 0.276723 0.799074"/>
  <limit upper="6.283185" lower="0.0" effort="100" velocity="100"/>
</joint>

<joint name="Joint1" type="revolute">
  <origin xyz="-0.013437 0.030771 0.24298" rpy="0 0 0"/>
  <parent link="base_link"/>
  <child link="link1_1"/>
  <axis xyz="0.031801 0.041072 0.99865"/>
  <limit upper="6.283185" lower="0.0" effort="100" velocity="100"/>
</joint>

<joint name="Joint2" type="revolute">
  <origin xyz="-0.347335 0.143287 0.142189" rpy="0 0 0"/>
  <parent link="link1_1"/>
  <child link="link2_1"/>
  <axis xyz="0.316319 0.947385 -0.049037"/>
  <limit upper="1.919862" lower="-1.919862" effort="100" velocity="100"/>
</joint>

<joint name="Joint3" type="revolute">
  <origin xyz="0.317778 -0.161276 -0.467719" rpy="0 0 0"/>
  <parent link="link2_1"/>
  <child link="link3_1"/>
  <axis xyz="-0.316319 -0.947385 0.049037"/>
  <limit upper="3.665191" lower="-0.523599" effort="100" velocity="100"/>
</joint>

<joint name="Joint4" type="revolute">
  <origin xyz="-0.435042 0.215016 0.990968" rpy="0 0 0"/>
  <parent link="link3_1"/>
  <child link="link4_1"/>
  <axis xyz="0.445442 -0.102692 0.889402"/>
  <limit upper="6.283185" lower="0.0" effort="100" velocity="100"/>
</joint>

</robot>
